Workbook
Name Slicer_city: #N/A
Name Slicer_peakhour: #N/A
Name Slicer_store_id: #N/A

Sheet blinkit_delivery_case_study
A1: order_id | B1: order_date | C1: city | D1: store_id | E1: order_time | F1: items_count | G1: order_value | H1: picking_time_min | I1: packing_time_min | J1: rider_assignment_time_min | K1: rider_waiting_time_min | L1: delivery_time_min | M1: total_delivery_time_min | N1: distance_km | O1: rider_id | P1: order_status | Q1: customer_rating
A2: ORD100001 | B2: 46222 | C2: Mumbai | D2: MUM03 | E2: 0.30625 | F2: 4 | G2: 462.38 | H2: 2.9 | I2: 0.9 | J2: 0.69 | K2: 0.51 | L2: 6.63 | M2: 11.63 | N2: 2.74 | O2: R016 | P2: Delivered | Q2: 4.3
A3: ORD100002 | B3: 46235 | C3: Pune | D3: PUN02 | E3: 0.39097222 | F3: 4 | G3: 346.91 | H3: 3.07 | I3: 0.83 | J3: 1.47 | K3: 0.78 | L3: 4.97 | M3: 11.12 | N3: 1.35 | O3: R019 | P3: Delivered | Q3: 5
A4: ORD100003 | B4: 46230 | C4: Pune | D4: PUN02 | E4: 0.89652778 | F4: 4 | G4: 395.51 | H4: 2.82 | I4: 0.94 | J4: 1.12 | K4: 0.76 | L4: 6.66 | M4: 12.3 | N4: 2.87 | O4: R023 | P4: Delivered | Q4: 5
A5: ORD100004 | B5: 46226 | C5: Pune | D5: PUN02 | E5: 0.97847222 | F5: 3 | G5: 605.94 | H5: 2.38 | I5: 0.75 | J5: 1.41 | K5: 0.76 | L5: 4.62 | M5: 9.92 | N5: 0.97 | O5: R025 | P5: Delivered | Q5: 4.3
A6: ORD100005 | B6: 46223 | C6: Mumbai | D6: MUM02 | E6: 0.97916667 | F6: 8 | G6: 800.58 | H6: 3.8 | I6: 1.24 | J6: 0.72 | K6: 0.77 | L6: 7.06 | M6: 13.59 | N6: 2.96 | O6: R016 | P6: Delivered | Q6: 5
A7: ORD100006 | B7: 46236 | C7: Pune | D7: PUN02 | E7: 0.78888889 | F7: 6 | G7: 571.04 | H7: 3.78 | I7: 1.03 | J7: 0.9 | K7: 0.78 | L7: 3.77 | M7: 10.26 | N7: 1.09 | O7: R054 | P7: Delivered | Q7: 5
A8: ORD100007 | B8: 46222 | C8: Pune | D8: PUN03 | E8: 0.66041667 | F8: 4 | G8: 284.74 | H8: 2.63 | I8: 1.01 | J8: 0.95 | K8: 0.75 | L8: 6.64 | M8: 11.98 | N8: 2.7 | O8: R073 | P8: Delivered | Q8: 5
A9: ORD100008 | B9: 46241 | C9: Pune | D9: PUN03 | E9: 0.76666667 | F9: 6 | G9: 580.03 | H9: 2.78 | I9: 1.02 | J9: 1.67 | K9: 0.85 | L9: 7.67 | M9: 13.99 | N9: 2.76 | O9: R001 | P9: Delivered | Q9: 3.9
A10: ORD100009 | B10: 46234 | C10: Pune | D10: PUN02 | E10: 0.48472222 | F10: 4 | G10: 715.39 | H10: 3.07 | I10: 0.66 | J10: 0.43 | K10: 0.89 | L10: 4.84 | M10: 9.89 | N10: 1.57 | O10: R042 | P10: Delivered | Q10: 4.4
A11: ORD100010 | B11: 46238 | C11: Mumbai | D11: MUM01 | E11: 0.077777778 | F11: 7 | G11: 390.24 | H11: 3.3 | I11: 1.26 | J11: 1.27 | K11: 0.73 | L11: 7.11 | M11: 13.67 | N11: 2.72 | O11: R019 | P11: Delivered | Q11: 4.5
A12: ORD100011 | B12: 46226 | C12: Pune | D12: PUN02 | E12: 0.00069444444 | F12: 5 | G12: 475.88 | H12: 2.14 | I12: 0.84 | J12: 1.58 | K12: 0.67 | L12: 6.06 | M12: 11.29 | N12: 2.43 | O12: R034 | P12: Delivered | Q12: 5
A13: ORD100012 | B13: 46226 | C13: Nagpur | D13: NAG02 | E13: 0.44513889 | F13: 6 | G13: 502.64 | H13: 3.42 | I13: 0.95 | J13: 0.39 | K13: 0.64 | L13: 5.78 | M13: 11.18 | N13: 1.72 | O13: R080 | P13: Delivered | Q13: 5
... A56: ORD100055 | B56: 46233 | C56: Mumbai | D56: MUM01 | E56: 0.60486111 | F56: 7 | G56: 772.42 | H56: 3.29 | I56: 1.11 | J56: 0.99 | K56: 0.75 | L56: 7.49 | M56: 13.63 | N56: 2.76 | O56: R042 | P56: Delivered | Q56: 4.7
A57: ORD100056 | B57: 46219 | C57: Pune | D57: PUN02 | E57: 0.44444444 | F57: 5 | G57: 613.55 | H57: 3.23 | I57: 0.84 | J57: 0.42 | K57: 0.81 | L57: 7.22 | M57: 12.52 | N57: 3 | O57: R013 | P57: Cancelled
A58: ORD100057 | B58: 46240 | C58: Nagpur | D58: NAG01 | E58: 0.32777778 | F58: 3 | G58: 315.65 | H58: 3.02 | I58: 0.77 | J58: 0.97 | K58: 0.67 | L58: 5.91 | M58: 11.34 | N58: 1.67 | O58: R036 | P58: Delivered | Q58: 5
A59: ORD100058 | B59: 46243 | C59: Nagpur | D59: NAG02 | E59: 0.10416667 | F59: 4 | G59: 833.74 | H59: 3.14 | I59: 0.78 | J59: 1.35 | K59: 1.03 | L59: 5.67 | M59: 11.97 | N59: 2.31 | O59: R013 | P59: Cancelled
A60: ORD100059 | B60: 46229 | C60: Mumbai | D60: MUM01 | E60: 0.99861111 | F60: 6 | G60: 719.79 | H60: 3.69 | I60: 0.95 | J60: 0.91 | K60: 0.56 | L60: 8.38 | M60: 14.49 | N60: 3.96 | O60: R012 | P60: Cancelled
A61: ORD100060 | B61: 46233 | C61: Nagpur | D61: NAG02 | E61: 0.91736111 | F61: 4 | G61: 604.78 | H61: 2.94 | I61: 0.85 | J61: 2.09 | K61: 1.35 | L61: 5.8 | M61: 13.03 | N61: 1.99 | O61: R037 | P61: Delivered | Q61: 4.7
A62: ORD100061 | B62: 46241 | C62: Mumbai | D62: MUM02 | E62: 0.18194444 | F62: 3 | G62: 459.23 | H62: 2.49 | I62: 0.69 | J62: 2.15 | K62: 1.27 | L62: 4.35 | M62: 10.95 | N62: 1.25 | O62: R074 | P62: Delivered | Q62: 5
A63: ORD100062 | B63: 46224 | C63: Pune | D63: PUN01 | E63: 0.099305556 | F63: 5 | G63: 327.3 | H63: 2.34 | I63: 0.91 | J63: 0.32 | K63: 0.53 | L63: 7.59 | M63: 11.69 | N63: 3.53 | O63: R073 | P63: Delivered | Q63: 4.9
A64: ORD100063 | B64: 46241 | C64: Pune | D64: PUN02 | E64: 0.23958333 | F64: 5 | G64: 433 | H64: 2.81 | I64: 0.72 | J64: 1.68 | K64: 0.81 | L64: 9.53 | M64: 15.55 | N64: 3.97 | O64: R052 | P64: Delivered | Q64: 3.6
A65: ORD100064 | B65: 46236 | C65: Pune | D65: PUN01 | E65: 0.43263889 | F65: 6 | G65: 695.97 | H65: 2.82 | I65: 1.06 | J65: 1.03 | K65: 0.94 | L65: 5.97 | M65: 11.82 | N65: 2.2 | O65: R071 | P65: Delivered | Q65: 4.4
A66: ORD100065 | B66: 46217 | C66: Pune | D66: PUN02 | E66: 0.70555556 | F66: 4 | G66: 839.23 | H66: 3.44 | I66: 0.87 | J66: 0.44 | K66: 0.48 | L66: 7.71 | M66: 12.94 | N66: 3.11 | O66: R002 | P66: Delivered | Q66: 4.6
A67: ORD100066 | B67: 46235 | C67: Pune | D67: PUN03 | E67: 0.61111111 | F67: 8 | G67: 777.78 | H67: 3.5 | I67: 1.09 | J67: 0.87 | K67: 0.78 | L67: 7.67 | M67: 13.91 | N67: 3.41 | O67: R056 | P67: Delivered | Q67: 4.5
A68: ORD100067 | B68: 46243 | C68: Mumbai | D68: MUM03 | E68: 0.00069444444 | F68: 5 | G68: 412.01 | H68: 2.94 | I68: 1.03 | J68: 1.04 | K68: 0.91 | L68: 4.07 | M68: 9.99 | N68: 1.53 | O68: R060 | P68: Delivered | Q68: 5
A69: ORD100068 | B69: 46230 | C69: Pune | D69: PUN03 | E69: 0.62222222 | F69: 6 | G69: 298.47 | H69: 3.31 | I69: 1.14 | J69: 1.66 | K69: 0.44 | L69: 5.58 | M69: 12.13 | N69: 1.76 | O69: R023 | P69: Delivered | Q69: 4.1
A70: ORD100069 | B70: 46243 | C70: Mumbai | D70: MUM03 | E70: 0.92152778 | F70: 3 | G70: 525.36 | H70: 2.48 | I70: 0.6 | J70: 1.97 | K70: 1.16 | L70: 7.52 | M70: 13.73 | N70: 3.56 | O70: R040 | P70: Delivered | Q70: 4.8
A71: ORD100070 | B71: 46222 | C71: Pune | D71: PUN03 | E71: 0.17569444 | F71: 10 | G71: 181.68 | H71: 4.59 | I71: 1.26 | J71: 1.63 | K71: 0.43 | L71: 8.43 | M71: 16.34 | N71: 3.72 | O71: R064 | P71: Delivered | Q71: 4.9
A72: ORD100071 | B72: 46227 | C72: Mumbai | D72: MUM01 | E72: 0.31388889 | F72: 3 | G72: 558.17 | H72: 2.24 | I72: 0.7 | J72: 0.36 | K72: 0.58 | L72: 6.15 | M72: 10.03 | N72: 2.71 | O72: R023 | P72: Delivered | Q72: 5
... A82: ORD100081 | B82: 46217 | C82: Mumbai | D82: MUM03 | E82: 0.27986111 | F82: 7 | G82: 799.03 | H82: 2.81 | I82: 1.27 | J82: 1.18 | K82: 0.49 | L82: 6.57 | M82: 12.32 | N82: 2.24 | O82: R025 | P82: Delivered | Q82: 4.6
A83: ORD100082 | B83: 46221 | C83: Pune | D83: PUN03 | E83: 0.10486111 | F83: 5 | G83: 417.72 | H83: 3.17 | I83: 0.79 | J83: 0.73 | K83: 0.44 | L83: 7.04 | M83: 12.17 | N83: 2.7 | O83: R013 | P83: Cancelled
A84: ORD100083 | B84: 46237 | C84: Mumbai | D84: MUM01 | E84: 0.036805556 | F84: 6 | G84: 391.6 | H84: 3.15 | I84: 0.67 | J84: 1.35 | K84: 0.71 | L84: 3 | M84: 8.88 | N84: 0.4 | O84: R070 | P84: Delivered | Q84: 4.8
A85: ORD100084 | B85: 46225 | C85: Mumbai | D85: MUM02 | E85: 0.79375 | F85: 4 | G85: 584.38 | H85: 2.17 | I85: 0.89 | J85: 2.54 | K85: 0.77 | L85: 5.9 | M85: 12.27 | N85: 2.18 | O85: R067 | P85: Delivered | Q85: 4.5
A86: ORD100085 | B86: 46219 | C86: Mumbai | D86: MUM01 | E86: 0.43541667 | F86: 4 | G86: 320.29 | H86: 2.57 | I86: 1.09 | J86: 0.3 | K86: 1.08 | L86: 6.38 | M86: 11.42 | N86: 2.42 | O86: R058 | P86: Delivered | Q86: 5
A87: ORD100086 | B87: 46237 | C87: Pune | D87: PUN02 | E87: 0.40694444 | F87: 6 | G87: 554.32 | H87: 2.86 | I87: 1.18 | J87: 1.22 | K87: 1.13 | L87: 4.55 | M87: 10.94 | N87: 1.16 | O87: R075 | P87: Delivered | Q87: 4.5
A88: ORD100087 | B88: 46233 | C88: Pune | D88: PUN03 | E88: 0.071527778 | F88: 6 | G88: 637.89 | H88: 3.23 | I88: 1.06 | J88: 1.16 | K88: 0.55 | L88: 6.03 | M88: 12.03 | N88: 2.55 | O88: R064 | P88: Delivered | Q88: 4.5
A89: ORD100088 | B89: 46241 | C89: Mumbai | D89: MUM03 | E89: 0.17569444 | F89: 5 | G89: 720.85 | H89: 3.37 | I89: 0.89 | J89: 1.08 | K89: 0.67 | L89: 7.16 | M89: 13.17 | N89: 2.02 | O89: R069 | P89: Delivered | Q89: 4.6
A90: ORD100089 | B90: 46227 | C90: Nagpur | D90: NAG01 | E90: 0.86805556 | F90: 7 | G90: 481.97 | H90: 2.68 | I90: 1.21 | J90: 1.89 | K90: 1.01 | L90: 10.13 | M90: 16.92 | N90: 4.03 | O90: R059 | P90: Delivered | Q90: 4.5
A91: ORD100090 | B91: 46217 | C91: Mumbai | D91: MUM01 | E91: 0.78819444 | F91: 4 | G91: 463.34 | H91: 2.72 | I91: 0.75 | J91: 0.58 | K91: 0.65 | L91: 8.64 | M91: 13.34 | N91: 3.62 | O91: R060 | P91: Cancelled
...

Sheet blinkit_stores
A1: store_id | B1: city | C1: store_capacity | D1: active_riders | E1: Peak_hour_Order | F1: Peak_hour_Order/ active_rider
A2: MUM01 | B2: Mumbai | C2: 80 | D2: 8 | E2: 5 | F2: =Table3[[#This Row],[Peak_hour_Order ]]/Table3[[#This Row],[active_riders]] -> 0.625
A3: MUM02 | B3: Mumbai | C3: 90 | D3: 7 | E3: 5 | F3: =Table3[[#This Row],[Peak_hour_Order ]]/Table3[[#This Row],[active_riders]] -> 0.71428571
A4: MUM03 | B4: Mumbai | C4: 75 | D4: 8 | E4: 3 | F4: =Table3[[#This Row],[Peak_hour_Order ]]/Table3[[#This Row],[active_riders]] -> 0.375
A5: NAG01 | B5: Nagpur | C5: 70 | D5: 7 | E5: 5 | F5: =Table3[[#This Row],[Peak_hour_Order ]]/Table3[[#This Row],[active_riders]] -> 0.71428571
A6: NAG02 | B6: Nagpur | C6: 85 | D6: 6 | E6: 9 | F6: =Table3[[#This Row],[Peak_hour_Order ]]/Table3[[#This Row],[active_riders]] -> 1.5
A7: PUN01 | B7: Pune | C7: 80 | D7: 9 | E7: 3 | F7: =Table3[[#This Row],[Peak_hour_Order ]]/Table3[[#This Row],[active_riders]] -> 0.33333333
A8: PUN02 | B8: Pune | C8: 95 | D8: 7 | E8: 6 | F8: =Table3[[#This Row],[Peak_hour_Order ]]/Table3[[#This Row],[active_riders]] -> 0.85714286
A9: PUN03 | B9: Pune | C9: 75 | D9: 8 | E9: 4 | F9: =Table3[[#This Row],[Peak_hour_Order ]]/Table3[[#This Row],[active_riders]] -> 0.5

Sheet Delivered_data
A1: order_id | B1: order_date | C1: week_start_date | D1: city | E1: store_id | F1: peak_order/rider | G1: order_time | H1: peakhour | I1: items_count | J1: order_value | K1: picking_time_min | L1: packing_time_min | M1: rider_assignment_time_min | N1: rider_waiting_time_min | O1: delivery_time_min | P1: total_delivery_time_min | Q1: distance_km | R1: rider_id | S1: order_status | T1: customer_rating
A2: ORD100001 | B2: 46222 | C2: =Delivered_data[[#This Row],[order_date]]-WEEKDAY(Delivered_data[[#This Row],[order_date]],2)+1 -> 46216 | D2: Mumbai | E2: MUM03 | F2: =_xlfn.XLOOKUP(Delivered_data[[#This Row],[store_id]],blinkit_stores!A:A,blinkit_stores!F:F,"not found") -> 0.375 | G2: 0.30625 | H2: =IF(AND(Delivered_data[[#This Row],[order_time]]>=TIME(19,0,0),Delivered_data[[#This Row],[order_time]]<=TIME(22,59,59)),"Peak","Non-Peak") -> Non-Peak | I2: 4 | J2: 462.38 | K2: 2.9 | L2: 0.9 | M2: 0.69 | N2: 0.51 | O2: 6.63 | P2: 11.63 | Q2: 2.74 | R2: R016 | S2: Delivered | T2: 4.3
A3: ORD100002 | B3: 46235 | C3: =Delivered_data[[#This Row],[order_date]]-WEEKDAY(Delivered_data[[#This Row],[order_date]],2)+1 -> 46230 | D3: Pune | E3: PUN02 | F3: =_xlfn.XLOOKUP(Delivered_data[[#This Row],[store_id]],blinkit_stores!A:A,blinkit_stores!F:F,"not found") -> 0.85714286 | G3: 0.39097222 | H3: =IF(AND(Delivered_data[[#This Row],[order_time]]>=TIME(19,0,0),Delivered_data[[#This Row],[order_time]]<=TIME(22,59,59)),"Peak","Non-Peak") -> Non-Peak | I3: 4 | J3: 346.91 | K3: 3.07 | L3: 0.83 | M3: 1.47 | N3: 0.78 | O3: 4.97 | P3: 11.12 | Q3: 1.35 | R3: R019 | S3: Delivered | T3: 5
A4: ORD100003 | B4: 46230 | C4: =Delivered_data[[#This Row],[order_date]]-WEEKDAY(Delivered_data[[#This Row],[order_date]],2)+1 -> 46230 | D4: Pune | E4: PUN02 | F4: =_xlfn.XLOOKUP(Delivered_data[[#This Row],[store_id]],blinkit_stores!A:A,blinkit_stores!F:F,"not found") -> 0.85714286 | G4: 0.89652778 | H4: =IF(AND(Delivered_data[[#This Row],[order_time]]>=TIME(19,0,0),Delivered_data[[#This Row],[order_time]]<=TIME(22,59,59)),"Peak","Non-Peak") -> Peak | I4: 4 | J4: 395.51 | K4: 2.82 | L4: 0.94 | M4: 1.12 | N4: 0.76 | O4: 6.66 | P4: 12.3 | Q4: 2.87 | R4: R023 | S4: Delivered | T4: 5
A5: ORD100004 | B5: 46226 | C5: =Delivered_data[[#This Row],[order_date]]-WEEKDAY(Delivered_data[[#This Row],[order_date]],2)+1 -> 46223 | D5: Pune | E5: PUN02 | F5: =_xlfn.XLOOKUP(Delivered_data[[#This Row],[store_id]],blinkit_stores!A:A,blinkit_stores!F:F,"not found") -> 0.85714286 | G5: 0.97847222 | H5: =IF(AND(Delivered_data[[#This Row],[order_time]]>=TIME(19,0,0),Delivered_data[[#This Row],[order_time]]<=TIME(22,59,59)),"Peak","Non-Peak") -> Non-Peak | I5: 3 | J5: 605.94 | K5: 2.38 | L5: 0.75 | M5: 1.41 | N5: 0.76 | O5: 4.62 | P5: 9.92 | Q5: 0.97 | R5: R025 | S5: Delivered | T5: 4.3
A6: ORD100005 | B6: 46223 | C6: =Delivered_data[[#This Row],[order_date]]-WEEKDAY(Delivered_data[[#This Row],[order_date]],2)+1 -> 46223 | D6: Mumbai | E6: MUM02 | F6: =_xlfn.XLOOKUP(Delivered_data[[#This Row],[store_id]],blinkit_stores!A:A,blinkit_stores!F:F,"not found") -> 0.71428571 | G6: 0.97916667 | H6: =IF(AND(Delivered_data[[#This Row],[order_time]]>=TIME(19,0,0),Delivered_data[[#This Row],[order_time]]<=TIME(22,59,59)),"Peak","Non-Peak") -> Non-Peak | I6: 8 | J6: 800.58 | K6: 3.8 | L6: 1.24 | M6: 0.72 | N6: 0.77 | O6: 7.06 | P6: 13.59 | Q6: 2.96 | R6: R016 | S6: Delivered | T6: 5
A7: ORD100006 | B7: 46236 | C7: =Delivered_data[[#This Row],[order_date]]-WEEKDAY(Delivered_data[[#This Row],[order_date]],2)+1 -> 46230 | D7: Pune | E7: PUN02 | F7: =_xlfn.XLOOKUP(Delivered_data[[#This Row],[store_id]],blinkit_stores!A:A,blinkit_stores!F:F,"not found") -> 0.85714286 | G7: 0.78888889 | H7: =IF(AND(Delivered_data[[#This Row],[order_time]]>=TIME(19,0,0),Delivered_data[[#This Row],[order_time]]<=TIME(22,59,59)),"Peak","Non-Peak") -> Non-Peak | I7: 6 | J7: 571.04 | K7: 3.78 | L7: 1.03 | M7: 0.9 | N7: 0.78 | O7: 3.77 | P7: 10.26 | Q7: 1.09 | R7: R054 | S7: Delivered | T7: 5
A8: ORD100007 | B8: 46222 | C8: =Delivered_data[[#This Row],[order_date]]-WEEKDAY(Delivered_data[[#This Row],[order_date]],2)+1 -> 46216 | D8: Pune | E8: PUN03 | F8: =_xlfn.XLOOKUP(Delivered_data[[#This Row],[store_id]],blinkit_stores!A:A,blinkit_stores!F:F,"not found") -> 0.5 | G8: 0.66041667 | H8: =IF(AND(Delivered_data[[#This Row],[order_time]]>=TIME(19,0,0),Delivered_data[[#This Row],[order_time]]<=TIME(22,59,59)),"Peak","Non-Peak") -> Non-Peak | I8: 4 | J8: 284.74 | K8: 2.63 | L8: 1.01 | M8: 0.95 | N8: 0.75 | O8: 6.64 | P8: 11.98 | Q8: 2.7 | R8: R073 | S8: Delivered | T8: 5
A9: ORD100008 | B9: 46241 | C9: =Delivered_data[[#This Row],[order_date]]-WEEKDAY(Delivered_data[[#This Row],[order_date]],2)+1 -> 46237 | D9: Pune | E9: PUN03 | F9: =_xlfn.XLOOKUP(Delivered_data[[#This Row],[store_id]],blinkit_stores!A:A,blinkit_stores!F:F,"not found") -> 0.5 | G9: 0.76666667 | H9: =IF(AND(Delivered_data[[#This Row],[order_time]]>=TIME(19,0,0),Delivered_data[[#This Row],[order_time]]<=TIME(22,59,59)),"Peak","Non-Peak") -> Non-Peak | I9: 6 | J9: 580.03 | K9: 2.78 | L9: 1.02 | M9: 1.67 | N9: 0.85 | O9: 7.67 | P9: 13.99 | Q9: 2.76 | R9: R001 | S9: Delivered | T9: 3.9
A10: ORD100009 | B10: 46234 | C10: =Delivered_data[[#This Row],[order_date]]-WEEKDAY(Delivered_data[[#This Row],[order_date]],2)+1 -> 46230 | D10: Pune | E10: PUN02 | F10: =_xlfn.XLOOKUP(Delivered_data[[#This Row],[store_id]],blinkit_stores!A:A,blinkit_stores!F:F,"not found") -> 0.85714286 | G10: 0.48472222 | H10: =IF(AND(Delivered_data[[#This Row],[order_time]]>=TIME(19,0,0),Delivered_data[[#This Row],[order_time]]<=TIME(22,59,59)),"Peak","Non-Peak") -> Non-Peak | I10: 4 | J10: 715.39 | K10: 3.07 | L10: 0.66 | M10: 0.43 | N10: 0.89 | O10: 4.84 | P10: 9.89 | Q10: 1.57 | R10: R042 | S10: Delivered | T10: 4.4
A11: ORD100010 | B11: 46238 | C11: =Delivered_data[[#This Row],[order_date]]-WEEKDAY(Delivered_data[[#This Row],[order_date]],2)+1 -> 46237 | D11: Mumbai | E11: MUM01 | F11: =_xlfn.XLOOKUP(Delivered_data[[#This Row],[store_id]],blinkit_stores!A:A,blinkit_stores!F:F,"not found") -> 0.625 | G11: 0.077777778 | H11: =IF(AND(Delivered_data[[#This Row],[order_time]]>=TIME(19,0,0),Delivered_data[[#This Row],[order_time]]<=TIME(22,59,59)),"Peak","Non-Peak") -> Non-Peak | I11: 7 | J11: 390.24 | K11: 3.3 | L11: 1.26 | M11: 1.27 | N11: 0.73 | O11: 7.11 | P11: 13.67 | Q11: 2.72 | R11: R019 | S11: Delivered | T11: 4.5
A12: ORD100011 | B12: 46226 | C12: =Delivered_data[[#This Row],[order_date]]-WEEKDAY(Delivered_data[[#This Row],[order_date]],2)+1 -> 46223 | D12: Pune | E12: PUN02 | F12: =_xlfn.XLOOKUP(Delivered_data[[#This Row],[store_id]],blinkit_stores!A:A,blinkit_stores!F:F,"not found") -> 0.85714286 | G12: 0.00069444444 | H12: =IF(AND(Delivered_data[[#This Row],[order_time]]>=TIME(19,0,0),Delivered_data[[#This Row],[order_time]]<=TIME(22,59,59)),"Peak","Non-Peak") -> Non-Peak | I12: 5 | J12: 475.88 | K12: 2.14 | L12: 0.84 | M12: 1.58 | N12: 0.67 | O12: 6.06 | P12: 11.29 | Q12: 2.43 | R12: R034 | S12: Delivered | T12: 5
A13: ORD100012 | B13: 46226 | C13: =Delivered_data[[#This Row],[order_date]]-WEEKDAY(Delivered_data[[#This Row],[order_date]],2)+1 -> 46223 | D13: Nagpur | E13: NAG02 | F13: =_xlfn.XLOOKUP(Delivered_data[[#This Row],[store_id]],blinkit_stores!A:A,blinkit_stores!F:F,"not found") -> 1.5 | G13: 0.44513889 | H13: =IF(AND(Delivered_data[[#This Row],[order_time]]>=TIME(19,0,0),Delivered_data[[#This Row],[order_time]]<=TIME(22,59,59)),"Peak","Non-Peak") -> Non-Peak | I13: 6 | J13: 502.64 | K13: 3.42 | L13: 0.95 | M13: 0.39 | N13: 0.64 | O13: 5.78 | P13: 11.18 | Q13: 1.72 | R13: R080 | S13: Delivered | T13: 5
... A230: ORD100240 | B230: 46232 | C230: =Delivered_data[[#This Row],[order_date]]-WEEKDAY(Delivered_data[[#This Row],[order_date]],2)+1 -> 46230 | D230: Pune | E230: PUN02 | F230: =_xlfn.XLOOKUP(Delivered_data[[#This Row],[store_id]],blinkit_stores!A:A,blinkit_stores!F:F,"not found") -> 0.85714286 | G230: 0.44097222 | H230: =IF(AND(Delivered_data[[#This Row],[order_time]]>=TIME(19,0,0),Delivered_data[[#This Row],[order_time]]<=TIME(22,59,59)),"Peak","Non-Peak") -> Non-Peak | I230: 7 | J230: 588.05 | K230: 3.2 | L230: 1.07 | M230: 1.4 | N230: 0.63 | O230: 4.35 | P230: 10.65 | Q230: 1.82 | R230: R066 | S230: Delivered | T230: 5

Sheet PIVOT
A3: Row Labels | B3: Average of total_delivery_time_min
A4: 46216 | B4: 11.706491
A5: 46223 | B5: 11.420877
A6: 46230 | B6: 12.449184
A7: 46237 | B7: 12.434091
A14: Row Labels | B14: Rider_waiting_time | C14: Rider_assignment_time
A15: Non-Peak | B15: 0.73920635 | C15: 1.0430688
A16: Peak | B16: 1.0295 | C16: 1.8925
A22: Row Labels | B22: Average of rider_assignment_time_min | C22: Average of rider_waiting_time_min | D22: Average of delivery_time_min
A23: Mumbai | B23: 1.2309589 | C23: 0.80369863 | D23: 5.8226027
A24: Nagpur | B24: 1.2437778 | C24: 0.85288889 | D24: 6.8062222
A25: Pune | B25: 1.1442342 | C25: 0.75531532 | D25: 6.1801802
A30: Row Labels | B30: Average of total_delivery_time_min
A31: 17 | B31: 11.745
A32: 18 | B32: 12.227143
A33: 19 | B33: 13.401538
A34: 20 | B34: 14.072
A35: 21 | B35: 12.846667
A36: 22 | B36: 13.715455
A37: 23 | B37: 10.844
A57: peakhour | B57: (All)
A59: Row Labels | B59: Average of total_delivery_time_min
A60: MUM01 | B60: 11.268261
A61: MUM02 | B61: 11.769565
A62: MUM03 | B62: 11.961481
A63: NAG01 | B63: 12.525238
A64: NAG02 | B64: 12.575833
A65: PUN01 | B65: 11.914138
A66: PUN02 | B66: 11.541522
A67: PUN03 | B67: 12.633889
A73: Row Labels | B73: Average of rider_assignment_time_min | C73: Average of rider_waiting_time_min | D73: Count of order_id
A74: 00 | B74: 1.1430769 | C74: 0.77 | D74: 13
A75: 01 | B75: 1.125 | C75: 0.6125 | D75: 4
A76: 02 | B76: 0.833 | C76: 0.706 | D76: 10
A77: 03 | B77: 1.0633333 | C77: 0.71 | D77: 9
A78: 04 | B78: 1.2 | C78: 0.78636364 | D78: 11
A79: 05 | B79: 0.89 | C79: 0.65833333 | D79: 6
A80: 06 | B80: 0.99333333 | C80: 0.69888889 | D80: 9
A81: 07 | B81: 0.94363636 | C81: 0.77272727 | D81: 11
A82: 08 | B82: 0.85714286 | C82: 0.66 | D82: 7
...

Sheet DASHBOARD
